Workbook

Sheet Nómina mensual
B2: Nómina mensual 2026 | I2: El sindicato de la enseñanza pública
B3: Elaborado por Manuel Pérez García. Secretario de Acción Sindical de ANPE ANDALUCÍA
B5: Cuerpo Docente | C5: 590-Profesores Enseñanza Secundaria | G5: Grupo prof: | H5: =IF($C$5="597-Maestros","A2",IF($C$5="596-Maestros de Taller de Artes Plásticas y Diseño","A2",IF($C$5="591-Profesores Técnicos de Formación Profesional","A2","A1"))) -> A1
B6: Funcionario | C6: Carrera | E6: Seleccionar en celdas sombreadas
B7: Años de Servicio | C7: 5
B8: Maestro de 1º y 2º de la ESO | C8: NO
B9: Nómina con Paga Extraordinaria | C9: NO | G9: Baleares
B10: Destino en Isla No Capitalina (Canarias) | C10: SI | G10: Elige Isla | H10: Formentera
B11: Tutor | C11: SI
B12: Cargo directivo | C12: Vicedirección
B13: Tipo de centro | C13: C
B14: % de retención de IRPF | C14: 0.24
B15: RETRIBUCIONES
C16: Andalucía | D16: Aragón | E16: Asturias | F16: Baleares (Islas) | G16: Canarias | H16: Cantabria | I16: Castilla La Mancha | J16: Castilla y León | K16: Cataluña | L16: Extremadura | M16: Galicia | N16: La Rioja | O16: Madrid | P16: Murcia | Q16: Valencia | R16: Ceuta y Melilla | S16: País Vasco | T16: Navarra
B17: Sueldo Base | C17: =+AD80 -> 1387.24 | D17: =+AE80 -> 1387.24 | E17: =+AF80 -> 1387.24 | F17: =+AG80 -> 1387.24 | G17: =+AC80 -> 1387.24 | H17: =+AH80 -> 1387.24 | I17: =+AI80 -> 1387.24 | J17: =+AJ80 -> 1387.24 | K17: =+AK80 -> 1387.24 | L17: =+AL80 -> 1387.24 | M17: =+AM80 -> 1387.24 | N17: =+AN80 -> 1387.24 | O17: =+AO80 -> 1387.24 | ... T17: =+AT80 -> 2258.75 | U17: Sueldo Base
B18: Trienios | C18: =AD82*INT($C$7/3) -> 53.39 | D18: =AE82*INT($C$7/3) -> 53.39 | E18: =AF82*INT($C$7/3) -> 53.39 | F18: =AG82*INT($C$7/3) -> 53.39 | G18: =IF($C$10="NO",AC82*INT($C$7/3),0) -> 0 | H18: =AH82*INT($C$7/3) -> 53.39 | I18: =AI82*INT($C$7/3) -> 53.39 | J18: =AJ82*INT($C$7/3) -> 53.39 | K18: =AK82*INT($C$7/3) -> 53.39 | L18: =AL82*INT($C$7/3) -> 53.39 | M18: =AM82*INT($C$7/3) -> 53.39 | N18: =AN82*INT($C$7/3) -> 53.39 | O18: =AO82*INT($C$7/3) -> 53.39 | ... S18: =AS82*INT($C$7/3) -> 53.39 | T18: =+AT95 -> 24.15 | U18: ANTIGÜEDAD NAVARRA
B19: Complemento Destino | C19: =+AD84 -> 729.14 | D19: =+AE84 -> 729.14 | E19: =+AF84 -> 736.54 | F19: =+AG84 -> 718.36 | G19: =+AC84 -> 728.32 | H19: =+AH84 -> 767.49 | I19: =+AI84 -> 729.14 | J19: =+AJ84 -> 729.14 | K19: =+AK84 -> 729.14 | L19: =+AL84 -> 729.14 | M19: =+AM84 -> 729.14 | N19: =+AN84 -> 729.14 | O19: =+AO84 -> 729.14 | ... T19: =+AT84 -> 0
B20: Complemento Específico General | C20: =+AD85 -> 881.46 | D20: =+AE85 -> 756.22 | E20: =+AF85 -> 708.37 | F20: =+AG85 -> 450.98 | G20: =+AC85 -> 757.35 | H20: =+AH85 -> 875.1 | I20: =+AI85 -> 282 | J20: =+AJ85 -> 294.2 | K20: =+AK85 -> 720.83 | L20: =+AL85 -> 520.73 | M20: =+AM85 -> 779.29 | N20: =+AN85 -> 909.64 | O20: =+AO85 -> 798.41 | ... T20: =+AT85 -> 756.23 | U20: Complemento Específico
B21: Complemento Específico Autonómico | C21: =+AD86 -> 0 | E21: =+AF86 -> 0 | F21: =+AG86 -> 429.57 | H21: =+AH86 -> 0 | I21: =+AI86 -> 585.97 | J21: =+AJ86 -> 424.79 | K21: =+AK86 -> 0 | L21: =+AL86 -> 181.99 | M21: =+AM86 -> 0 | N21: =+AN86 -> 0 | O21: =+AO86 -> 0 | ... R21: =+AR86 -> 0 | T21: =+AT86 -> 0
B22: Sin Sexenio | E22: =IF($C$7<6,+AF87,0) -> 113.85 | F22: =+AG87 -> 0 | H22: =IF($C$7<6,AH87,0) -> 35.77 | P22: =+AP87 -> 0 | U22: 5 años
B23: 1º Sexenio | C23: =IF($C$7>5,AD88,0) -> 0 | D23: =IF($C$7>5,AE88,0) -> 0 | E23: =IF($C$7>5,AF88,0) -> 0 | F23: =IF($C$7>5,AG88,0) -> 0 | G23: =IF($C$7>5,AC88,0) -> 0 | H23: =IF($C$7>5,AH88,0) -> 0 | I23: =IF($C$7>5,AI88,0) -> 0 | J23: =IF($C$7>5,AJ88,0) -> 0 | K23: =IF($C$7>5,AK88,0) -> 0 | L23: =IF($C$7>5,AL88,0) -> 0 | M23: =IF($C$7>5,AM88,0) -> 0 | N23: =IF($C$7>5,AN88,0) -> 0 | O23: =IF($C$7>5,AO88,0) -> 0 | ... S23: =IF($C$7>5,AS88,0) -> 0 | U23: 6 años y 7 meses
B24: 2º Sexenio | C24: =IF($C$7>11,AD89,0) -> 0 | D24: =IF($C$7>11,AE89,0) -> 0 | E24: =IF($C$7>11,AF89,0) -> 0 | F24: =IF($C$7>11,AG89,0) -> 0 | G24: =IF($C$7>11,AC89,0) -> 0 | H24: =IF($C$7>11,AH89,0) -> 0 | I24: =IF($C$7>11,AI89,0) -> 0 | J24: =IF($C$7>11,AJ89,0) -> 0 | K24: =IF($C$7>11,AK89,0) -> 0 | L24: =IF($C$7>11,AL89,0) -> 0 | M24: =IF($C$7>11,AM89,0) -> 0 | N24: =IF($C$7>11,AN89,0) -> 0 | O24: =IF($C$7>11,AO89,0) -> 0 | ... S24: =IF($C$7>11,AS89,0) -> 0 | U24: 10 años
B25: 3º Sexenio | C25: =IF($C$7>17,AD90,0) -> 0 | D25: =IF($C$7>17,AE90,0) -> 0 | E25: =IF($C$7>17,AF90,0) -> 0 | F25: =IF($C$7>17,AG90,0) -> 0 | G25: =IF($C$7>17,AC90,0) -> 0 | H25: =IF($C$7>17,AH90,0) -> 0 | I25: =IF($C$7>17,AI90,0) -> 0 | J25: =IF($C$7>17,AJ90,0) -> 0 | K25: =IF($C$7>17,AK90,0) -> 0 | L25: =IF($C$7>17,AL90,0) -> 0 | M25: =IF($C$7>17,AM90,0) -> 0 | N25: =IF($C$7>17,AN90,0) -> 0 | O25: =IF($C$7>17,AO90,0) -> 0 | ... S25: =IF($C$7>17,AS90,0) -> 0 | U25: 13 años y 2 meses
B26: 4º Sexenio | C26: =IF($C$7>23,AD91,0) -> 0 | D26: =IF($C$7>23,AE91,0) -> 0 | E26: =IF($C$7>23,AF91,0) -> 0 | F26: =IF($C$7>23,AG91,0) -> 0 | G26: =IF($C$7>23,AC91,0) -> 0 | H26: =IF($C$7>23,AH91,0) -> 0 | I26: =IF($C$7>23,AI91,0) -> 0 | J26: =IF($C$7>23,AJ91,0) -> 0 | K26: =IF($C$7>23,AK91,0) -> 0 | L26: =IF($C$7>23,AL91,0) -> 0 | M26: =IF($C$7>23,AM91,0) -> 0 | N26: =IF($C$7>23,AN91,0) -> 0 | O26: =IF($C$7>23,AO91,0) -> 0 | ... S26: =IF($C$7>23,AS91,0) -> 0 | U26: 15 años
B27: 5º Sexenio | C27: =IF($C$7>29,AD92,0) -> 0 | D27: =IF($C$7>29,AE92,0) -> 0 | E27: =IF($C$7>29,AF92,0) -> 0 | F27: =IF($C$7>29,AG92,0) -> 0 | G27: =IF($C$7>29,AC92,0) -> 0 | H27: =IF($C$7>29,AH92,0) -> 0 | I27: =IF($C$7>29,AI92,0) -> 0 | J27: =IF($C$7>29,AJ92,0) -> 0 | K27: =IF($C$7>29,AK92,0) -> 0 | L27: =IF($C$7>29,AL92,0) -> 0 | M27: =IF($C$7>29,AM92,0) -> 0 | N27: =IF($C$7>29,AN92,0) -> 0 | O27: =IF($C$7>29,AO92,0) -> 0 | ... S27: =IF($C$7>29,AS92,0) -> 0 | U27: 19 años y 9 meses
B28: =IF(C11="si","Tutoría"," ") -> Tutoría | C28: =IF($C$11="si",AD93," ") -> 31.97 | D28: =IF($C$11="si",AE93," ") -> 0 | E28: =IF($C$11="si",AF93," ") -> 0 | F28: =IF($C$11="si",AG93," ") -> 36.71 | G28: =IF($C$11="si",AC93," ") -> 35 | H28: =IF($C$11="si",AH93," ") -> 0 | I28: =IF($C$11="si",AI93," ") -> 0 | J28: =IF($C$11="si",AJ93," ") -> 0 | K28: =IF($C$11="si",AK93," ") -> 93.6 | L28: =IF($C$11="si",AL93," ") -> 47.72 | M28: =IF($C$11="si",AM93," ") -> 66.04 | N28: =IF($C$11="si",AN93," ") -> 0 | O28: =IF($C$11="si",AO93," ") -> 70.94 | ... S28: =IF($C$11="si",AS93," ") -> 62.45 | U28: 20 años
B29: Cargo directivo | C29: =IF($H$5="A1",INDEX(Retribuciones!W53:AA58,MATCH($C$13,Retribuciones!Q53:Q58,0),MATCH($C$12,Retribuciones!W52:AA52,0)),INDEX(Retribuciones!R53:V58,MATCH($C$13,Retribuciones!Q53:Q58,0),MATCH($C$12,Retribuciones!R52:V52,0))) -> 350.9 | D29: =IF($H$5="A1",INDEX(Retribuciones!W89:AA94,MATCH($C$13,Retribuciones!Q89:Q94,0),MATCH($C$12,Retribuciones!W88:AA88,0)),INDEX(Retribuciones!R89:V94,MATCH($C$13,Retribuciones!Q89:Q94,0),MATCH($C$12,Retribuciones!R88:V88,0))) -> 332.96 | E29: =IF($H$5="A1",INDEX(Retribuciones!W125:AA130,MATCH($C$13,Retribuciones!Q125:Q130,0),MATCH($C$12,Retribuciones!W124:AA124,0)),INDEX(Retribuciones!R125:V130,MATCH($C$13,Retribuciones!Q125:Q130,0),MATCH($C$12,Retribuciones!R124:V124,0))) -> 0 | F29: =IF($H$5="A1",INDEX(Retribuciones!W161:AA166,MATCH($C$13,Retribuciones!Q161:Q166,0),MATCH($C$12,Retribuciones!W160:AA160,0)),INDEX(Retribuciones!R161:V166,MATCH($C$13,Retribuciones!Q161:Q166,0),MATCH($C$12,Retribuciones!R160:V160,0))) -> 0 | G29: =IF($H$5="A1",INDEX(Retribuciones!W13:AA18,MATCH($C$13,Retribuciones!Q13:Q18,0),MATCH($C$12,Retribuciones!W12:AA12,0)),INDEX(Retribuciones!R13:V18,MATCH($C$13,Retribuciones!Q13:Q18,0),MATCH($C$12,Retribuciones!R12:V12,0))) -> 253.88 | H29: =IF($H$5="A1",INDEX(Retribuciones!W197:AA202,MATCH($C$13,Retribuciones!Q197:Q202,0),MATCH($C$12,Retribuciones!W196:AA196,0)),INDEX(Retribuciones!R197:V197,MATCH($C$13,Retribuciones!Q197:Q202,0),MATCH($C$12,Retribuciones!R196:V196,0))) -> 410.05 | I29: =IF($H$5="A1",INDEX(Retribuciones!W233:AA238,MATCH($C$13,Retribuciones!Q233:Q238,0),MATCH($C$12,Retribuciones!W232:AA232,0)),INDEX(Retribuciones!R233:V238,MATCH($C$13,Retribuciones!Q233:Q238,0),MATCH($C$12,Retribuciones!R232:V232,0))) -> 0 | J29: =IF($H$5="A1",INDEX(Retribuciones!W269:AA274,MATCH($C$13,Retribuciones!Q269:Q274,0),MATCH($C$12,Retribuciones!W268:AA268,0)),INDEX(Retribuciones!R269:V274,MATCH($C$13,Retribuciones!Q269:Q274,0),MATCH($C$12,Retribuciones!R268:V268,0))) -> 0 | K29: =IF($H$5="A1",INDEX(Retribuciones!W305:AA310,MATCH($C$13,Retribuciones!Q305:Q310,0),MATCH($C$12,Retribuciones!W304:AA304,0)),INDEX(Retribuciones!R305:V310,MATCH($C$13,Retribuciones!Q305:Q310,0),MATCH($C$12,Retribuciones!R304:V304,0))) -> 0 | L29: =IF($H$5="A1",INDEX(Retribuciones!W341:AA346,MATCH($C$13,Retribuciones!Q341:Q346,0),MATCH($C$12,Retribuciones!W340:AA340,0)),INDEX(Retribuciones!R341:V346,MATCH($C$13,Retribuciones!Q341:Q346,0),MATCH($C$12,Retribuciones!R340:V340,0))) -> 213.95 | M29: =IF($H$5="A1",INDEX(Retribuciones!W378:AA383,MATCH($C$13,Retribuciones!Q378:Q383,0),MATCH($C$12,Retribuciones!W377:AA377,0)),INDEX(Retribuciones!R378:V383,MATCH($C$13,Retribuciones!Q378:Q383,0),MATCH($C$12,Retribuciones!R377:V377,0))) -> 308.04 | N29: =IF($H$5="A1",INDEX(Retribuciones!W413:AA418,MATCH($C$13,Retribuciones!Q413:Q418,0),MATCH($C$12,Retribuciones!W412:AA412,0)),INDEX(Retribuciones!R413:V418,MATCH($C$13,Retribuciones!Q413:Q418,0),MATCH($C$12,Retribuciones!R412:V412,0))) -> 0 | O29: =IF($H$5="A1",INDEX(Retribuciones!W449:AA454,MATCH($C$13,Retribuciones!Q449:Q454,0),MATCH($C$12,Retribuciones!W448:AA448,0)),INDEX(Retribuciones!R449:V454,MATCH($C$13,Retribuciones!Q449:Q454,0),MATCH($C$12,Retribuciones!R448:V448,0))) -> 596.262 | P29: =IF($H$5="A1",INDEX(Retribuciones!W485:AA490,MATCH($C$13,Retribuciones!Q485:Q490,0),MATCH($C$12,Retribuciones!W484:AA484,0)),INDEX(Retribuciones!R485:V490,MATCH($C$13,Retribuciones!Q485:Q490,0),MATCH($C$12,Retribuciones!R484:V484,0))) -> 0 | Q29: =IF($H$5="A1",INDEX(Retribuciones!W521:AA526,MATCH($C$13,Retribuciones!Q521:Q526,0),MATCH($C$12,Retribuciones!W520:AA520,0)),INDEX(Retribuciones!R521:V526,MATCH($C$13,Retribuciones!Q521:Q526,0),MATCH($C$12,Retribuciones!R520:V520,0))) -> 483.99 | R29: =IF($H$5="A1",INDEX(Retribuciones!W557:AA562,MATCH($C$13,Retribuciones!Q557:Q562,0),MATCH($C$12,Retribuciones!W556:AA556,0)),INDEX(Retribuciones!R557:V562,MATCH($C$13,Retribuciones!Q557:Q562,0),MATCH($C$12,Retribuciones!R556:V556,0))) -> 0 | S29: =IF($H$5="A1",INDEX(Retribuciones!W593:AA598,MATCH($C$13,Retribuciones!Q593:Q598,0),MATCH($C$12,Retribuciones!W592:AA592,0)),INDEX(Retribuciones!R593:V598,MATCH($C$13,Retribuciones!Q593:Q598,0),MATCH($C$12,Retribuciones!R592:V592,0))) -> 0 | T29: =IF($H$5="A1",INDEX(Retribuciones!W629:AA634,MATCH($C$13,Retribuciones!Q629:Q634,0),MATCH($C$12,Retribuciones!W628:AA628,0)),INDEX(Retribuciones!R629:V634,MATCH($C$13,Retribuciones!Q629:Q634,0),MATCH($C$12,Retribuciones!R628:V628,0))) -> 338.81
B30: Residencia | F30: =IF($H$10="Mallorca",AG94,AG95) -> 693.08 | G30: =IF($C$10="si",AC95,AC94) -> 534.9 | R30: =+AR95 -> 1102.57 | U30: 25 años
B31: Trienio Residencia | G31: =IF($C$10="si",AC96*INT($C$7/3)," ") -> 37.63 | R31: =AR94*INT($C$7/3) -> 66.76 | U31: 26 años y 4 meses
B32: Fondos adicionales/Especial dedicación/Carrera Docente | D32: =+AE98 -> 0 | E32: =IF($C$7>10,AF99,IF(AND($C$7>5,$C$7<11),AF98,0)) -> 0 | F32: =IF($C$7>12,+AG99,IF($C$7>6,+AG98,0)) -> 0 | J32: =+AJ98 -> 27.04 | L32: =+AL98 -> 0 | N32: =+AN98 -> 0 | U32: 30 años
B33: =IF(C8="si","Adicional maestros 1º y 2º ESO"," ") | C33: =IF($C$8="si",AD97," ") | D33: =IF($C$8="si",AE97," ") | E33: =IF($C$8="si",AF97," ") | F33: =IF($C$8="si",AG97," ") | G33: =IF($C$8="si",AC97," ") | H33: =IF($C$8="si",AH97," ") | I33: =IF($C$8="si",AI97," ") | J33: =IF($C$8="si",AJ97," ") | K33: =IF($C$8="si",AK97," ") | L33: =IF($C$8="si",AL97," ") | M33: =IF($C$8="si",AM97," ") | N33: =IF($C$8="si",AN97," ") | O33: =IF($C$8="si",AO97," ") | ... T33: =IF($C$8="si",AT97," ") | U33: 32 años y 11 meses
B34: =IF($C$9="si","Paga extra, Sueldo Base"," ") | C34: =IF($C$9="si",AD81," ") | D34: =IF($C$9="si",AE81," ") | E34: =IF($C$9="si",AF81," ") | F34: =IF($C$9="si",AG81," ") | G34: =IF($C$9="si",AC81," ") | H34: =IF($C$9="si",AH81," ") | I34: =IF($C$9="si",AI81," ") | J34: =IF($C$9="si",AJ81," ") | K34: =IF($C$9="si",AK81," ") | L34: =IF($C$9="si",AL81," ") | M34: =IF($C$9="si",AM81," ") | N34: =IF($C$9="si",AN81," ") | O34: =IF($C$9="si",AO81," ") | ... S34: =IF($C$9="si",AS81," ") | U34: 35 años
B35: =IF($C$9="si","Paga extra, Trienios"," ") | C35: =IF($C$9="si",AD83*INT($C$7/3)," ") | D35: =IF($C$9="si",AE83*INT($C$7/3)," ") | E35: =IF($C$9="si",AF83*INT($C$7/3)," ") | F35: =IF($C$9="si",AG83*INT($C$7/3)," ") | G35: =IF($C$9="si",AC83*INT($C$7/3)," ") | H35: =IF($C$9="si",AH83*INT($C$7/3)," ") | I35: =IF($C$9="si",AI83*INT($C$7/3)," ") | J35: =IF($C$9="si",AJ83*INT($C$7/3)," ") | K35: =IF($C$9="si",AK83*INT($C$7/3)," ") | L35: =IF($C$9="si",AL83*INT($C$7/3)," ") | M35: =IF($C$9="si",AM83*INT($C$7/3)," ") | N35: =IF($C$9="si",AN83*INT($C$7/3)," ") | O35: =IF($C$9="si",AO83*INT($C$7/3)," ") | ... S35: =IF($C$9="si",AS83*INT($C$7/3)," ") | U35: 40 años
B36: =IF($C$9="si","Paga extra, Complemento Destino"," ") | C36: =IF($C$9="si",AD84," ") | D36: =IF($C$9="si",AE84," ") | E36: =IF($C$9="si",AF84," ") | F36: =IF($C$9="si",AG84," ") | G36: =IF($C$9="si",AC84," ") | H36: =IF($C$9="si",AH84," ") | I36: =IF($C$9="si",AI84," ") | J36: =IF($C$9="si",AJ84," ") | K36: =IF($C$9="si",AK84," ") | L36: =IF($C$9="si",AL84," ") | M36: =IF($C$9="si",AM84," ") | N36: =IF($C$9="si",AN84," ") | O36: =IF($C$9="si",AO84," ") | ... S36: =IF($C$9="si",AS84," ") | T36: =IF($C$9="si",SUM(T17:T35),0) -> 0 | U36: < Extra Navarra
B37: =IF($C$9="si","Paga extra, Complemento Específico"," ") | C37: =IF($C$9="si",AD85," ") | E37: =IF($C$9="si",AF85," ") | F37: =IF($C$9="si",AG85," ") | G37: =IF($C$9="si",AC86," ") | H37: =IF($C$9="si",AH85," ") | I37: =IF($C$9="si",AI85," ") | J37: =IF($C$9="si",AJ85," ") | K37: =IF($C$9="si",AK85," ") | L37: =IF($C$9="si",AL85," ") | M37: =IF($C$9="si",AM85," ") | N37: =IF($C$9="si",AN85," ") | O37: =IF($C$9="si",AO85," ") | P37: =IF($C$9="si",AP85*70%," ") | Q37: =IF($C$9="si",AQ85," ") | R37: =IF($C$9="si",AR85," ") | S37: =IF($C$9="si",AS85," ") | T37: =IF($C$9="s",AT85*0.78," ")
B38: =IF($C$9="si","Paga extra, Complemento Específico Autonómico"," ") | C38: =IF($C$9="si",AD86," ") | D38: =IF($C$9="si",AE86," ") | E38: =IF($C$9="si",AF86," ") | F38: =IF($C$9="si",AG86," ") | H38: =IF($C$9="si",AH86," ") | I38: =IF($C$9="si",AI86," ") | J38: =IF($C$9="si",AJ86," ") | K38: =IF($C$9="si",AK86," ") | L38: =IF($C$9="si",AL86," ") | M38: =IF($C$9="si",AM86," ") | N38: =IF($C$9="si",AN86," ") | O38: =IF($C$9="si",AO86," ") | P38: =IF($C$9="si",AP86*60%," ") | Q38: =IF($C$9="si",AQ86," ") | R38: =IF($C$9="si",AR86," ") | S38: =IF($C$9="si",AS86," ") | T38: =IF($C$9="s",AT86*0.78," ")
B39: =IF($C$9="si","Paga extra, Complemento Sexenios"," ") | C39: =IF($C$9="si",SUM(C22:C27)," ") | D39: =IF($C$9="si",SUM(D22:D27)," ") | E39: =IF($C$9="si",SUM(E22:E27)," ") | F39: =IF($C$9="si",SUM(F22:F27)," ") | G39: =IF($C$9="si",SUM(G22:G27)," ") | H39: =IF($C$9="si",SUM(H22:H27)," ") | I39: =IF($C$9="si",SUM(I22:I27)," ") | J39: =IF($C$9="si",SUM(J22:J27)," ") | ... O39: =IF($C$9="si",SUM(O22:O27)," ") | P39: =IF($C$9="si",SUM(P23:P27)*64%," ") | Q39: =IF($C$9="si",SUM(Q22:Q27)," ") | R39: =IF($C$9="si",SUM(R22:R27)," ") | S39: =IF($C$9="si",SUM(S22:S27)," ") | T39: =IF($C$9="s",(T23+T24+T25+T26+T27)*0.78," ")
B40: =IF($C$9="si","Productividad semestral"," ") | C40: =IF($C$9="si",AD99," ") | D40: =IF($C$9="si",AE99," ") | F40: =IF($C$9="si",AG99," ") | G40: =IF($C$9="si",AC99," ") | H40: =IF($C$9="si",AH99," ") | I40: =IF($C$9="si",AI99," ") | J40: =IF($C$9="si",AJ99," ") | K40: =IF($C$9="si",AK99," ") | L40: =IF($C$9="si",AL99," ") | M40: =IF($C$9="si",AM99," ") | N40: =IF($C$9="si",AN99," ") | O40: =IF($C$9="si",AO99," ") | ... S40: =IF($C$9="si",AS99," ") | T40: =IF($C$9="s",AT99," ")
B41: SUELDO BRUTO MENSUAL | C41: =SUM(C17:C39) -> 3434.1 | D41: =SUM(D17:D40) -> 3258.95 | E41: =SUM(E17:E39) -> 2999.39 | F41: =SUM(F17:F39) -> 3769.33 | G41: =SUM(G17:G39) -> 3734.32 | H41: =SUM(H17:H39) -> 3529.04 | I41: =SUM(I17:I39) -> 3037.74 | J41: =SUM(J17:J39) -> 2915.8 | K41: =SUM(K17:K39) -> 2984.2 | L41: =SUM(L17:L39) -> 3134.16 | ... O41: =SUM(O17:O39) -> 3635.382 | P41: =SUM(P17:P40) -> 3047.55 | Q41: =SUM(Q17:Q39) -> 3384.76 | R41: =SUM(R17:R39) -> 3836.24 | S41: =SUM(S17:S39) -> 3355.04 | T41: =SUM(T17:T21)+T36 -> 3039.13
B43: DESCUENTOS
...

Sheet Retribuciones
B1: Cuerpo Docente | C1: =+'Nómina mensual'!C5:E5 -> 590-Profesores Enseñanza Secundaria | F1: Grupo prof: | G1: ='Nómina mensual'!H5 -> A1 | I1: Sin cargo
B2: Funcionario | C2: =+'Nómina mensual'!C6:E6 -> Carrera | E2: IMPORTANTE: PARA ACTUALIZAR CAMBIAR SÓLO LAS CELDAS SOMBREADAS | I2: Dirección | L2: A
B3: Años de Servicio a efectos de trienios | C3: =+'Nómina mensual'!C7:E7 -> 5 | I3: Vicedirección | L3: B
B4: Maestro de Primero y Segundo de la ESO | C4: =+'Nómina mensual'!C8:E8 -> NO | I4: Jefatura de Estudios | L4: C
B5: Nómina con Paga Extraordinaria | C5: =+'Nómina mensual'!C9:E9 -> NO | I5: Secretaría | L5: D
B6: Destino en Isla No Capitalina | C6: =+'Nómina mensual'!C10:E10 -> SI | L6: E
B7: Tutor | C7: =+'Nómina mensual'!C11:E11 -> SI | L7: F
B8: Cargo directivo | C8: ='Nómina mensual'!C12:D12 -> Vicedirección
C10: =+E11 -> Canarias
C11: =+C1 -> 590-Profesores Enseñanza Secundaria | E11: Canarias | F11: 597-Maestros | G11: 591-Profesores Técnicos de Formación Profesional | H11: 596-Maestros de Taller de Artes Plásticas y Diseño | I11: 590-Profesores Enseñanza Secundaria | J11: 592-Profesores de Escuelas Oficiales de Idiomas | K11: 594-Profesores de Música y Artes Escénicas | L11: 595-Profesores de Artes Plásticas y Diseño | M11: 511-Catedráticos | N11: 510-Inspección | O11: INSPECCION | P11: ACT. 02/26 | Q11: A2 | W11: A1
B12: Grupo | C12: =IF($C$11=$F$11,F12,IF($C$11=G$11,G12,IF($C$11=H$11,H12,IF($C$11=I$11,I12,IF($C$11=J$11,J12,IF($C$11=K$11,K12,IF($C$11=L$11,L12,IF($C$11=M$11,M12,N12)))))))) -> A1 | E12: Grupo | F12: A2 | G12: A2 | H12: A2 | I12: A1 | J12: A1 | K12: A1 | L12: A1 | M12: A1 | N12: A1 | R12: Sin cargo | S12: Dirección | T12: Vicedirección | U12: Jefatura de Estudios | V12: Secretaría | W12: Sin cargo | X12: Dirección | Y12: Vicedirección | Z12: Jefatura de Estudios | AA12: Secretaría
B13: =+E13 -> 24 | C13: =IF($C$11=$F$11,F13,IF($C$11=G$11,G13,IF($C$11=H$11,H13,IF($C$11=I$11,I13,IF($C$11=J$11,J13,IF($C$11=K$11,K13,IF($C$11=L$11,L13,IF($C$11=M$11,M13,N13)))))))) -> 24 | E13: =+H13 -> 24 | F13: 21 | G13: 24 | H13: 24 | I13: 24 | J13: 24 | K13: 24 | L13: 24 | M13: 26 | N13: 26 | Q13: A | R13: 0 | S13: 552.34 | T13: 226.64 | U13: =T13 -> 226.64 | V13: =U13 -> 226.64 | W13: 0 | X13: 694.22 | Y13: 341.27 | Z13: =Y13 -> 341.27 | AA13: =Z13 -> 341.27
B14: Sueldo Base | C14: =IF($C$11=$F$11,F14,IF($C$11=G$11,G14,IF($C$11=H$11,H14,IF($C$11=I$11,I14,IF($C$11=J$11,J14,IF($C$11=K$11,K14,IF($C$11=L$11,L14,IF($C$11=M$11,M14,N14)))))))) -> 1387.24 | E14: Sueldo Base | F14: =+F54 -> 1199.52 | G14: =+G54 -> 1199.52 | H14: =+H54 -> 1199.52 | I14: =+I54 -> 1387.24 | J14: =+J54 -> 1387.24 | K14: =+K54 -> 1387.24 | L14: =+L54 -> 1387.24 | M14: =+M54 -> 1387.24 | N14: =+N54 -> 1387.24 | Q14: B | R14: 0 | S14: 503.95 | T14: 217.21 | U14: =T14 -> 217.21 | V14: =U14 -> 217.21 | W14: 0 | X14: 617.53 | Y14: 327.09 | Z14: =Y14 -> 327.09 | AA14: =Z14 -> 327.09
B15: Extra Sueldo Base | C15: =IF($C$11=$F$11,F15,IF($C$11=G$11,G15,IF($C$11=H$11,H15,IF($C$11=I$11,I15,IF($C$11=J$11,J15,IF($C$11=K$11,K15,IF($C$11=L$11,L15,IF($C$11=M$11,M15,N15)))))))) -> 856.05 | E15: Extra Sueldo Base | F15: =+F55 -> 874.83 | G15: =+G55 -> 874.83 | H15: =+H55 -> 874.83 | I15: =+I55 -> 856.05 | J15: =+J55 -> 856.05 | K15: =+K55 -> 856.05 | L15: =+L55 -> 856.05 | M15: =+M55 -> 856.05 | N15: =+N55 -> 856.05 | Q15: C | R15: 0 | S15: 380.04 | T15: 203.02 | U15: =T15 -> 203.02 | V15: =U15 -> 203.02 | W15: 0 | X15: 556.11 | Y15: 253.88 | Z15: =Y15 -> 253.88 | AA15: =Z15 -> 253.88
B16: Trienios | C16: =IF($C$11=$F$11,F16,IF($C$11=G$11,G16,IF($C$11=H$11,H16,IF($C$11=I$11,I16,IF($C$11=J$11,J16,IF($C$11=K$11,K16,IF($C$11=L$11,L16,IF($C$11=M$11,M16,N16)))))))) -> 53.39 | E16: Trienios | F16: =+F56 -> 43.54 | G16: =+G56 -> 43.54 | H16: =+H56 -> 43.54 | I16: =+I56 -> 53.39 | J16: =+J56 -> 53.39 | K16: =+K56 -> 53.39 | L16: =+L56 -> 53.39 | M16: =+M56 -> 53.39 | N16: =+N56 -> 53.39 | Q16: D | R16: 0 | S16: 289.17 | U16: 158.18 | V16: =U16 -> 158.18 | W16: 0 | X16: 506.52 | Y16: 203.13 | Z16: =Y16 -> 203.13 | AA16: =Z16 -> 203.13
B17: Extra Trienio | C17: =IF($C$11=$F$11,F17,IF($C$11=G$11,G17,IF($C$11=H$11,H17,IF($C$11=I$11,I17,IF($C$11=J$11,J17,IF($C$11=K$11,K17,IF($C$11=L$11,L17,IF($C$11=M$11,M17,N17)))))))) -> 32.96 | E17: Extra Trienio | F17: =+F57 -> 31.74 | G17: =+G57 -> 31.74 | H17: =+H57 -> 31.74 | I17: =+I57 -> 32.96 | J17: =+J57 -> 32.96 | K17: =+K57 -> 32.96 | L17: =+L57 -> 32.96 | M17: =+M57 -> 32.96 | N17: =+N57 -> 32.96 | Q17: E | R17: 0 | S17: 195.96 | V17: 106.25 | W17: 0
B18: Complemento Destino | C18: =IF($C$11=$F$11,F18,IF($C$11=G$11,G18,IF($C$11=H$11,H18,IF($C$11=I$11,I18,IF($C$11=J$11,J18,IF($C$11=K$11,K18,IF($C$11=L$11,L18,IF($C$11=M$11,M18,N18)))))))) -> 728.32 | E18: Complemento Destino | F18: 591.43 | G18: 728.32 | H18: =+G18 -> 728.32 | I18: =+H18 -> 728.32 | J18: =+I18 -> 728.32 | K18: =+J18 -> 728.32 | L18: =+K18 -> 728.32 | M18: 872.33 | N18: =+M18 -> 872.33 | Q18: F | R18: 0 | S18: 122.79 | W18: 0
B19: Complemento Específico | C19: =IF($C$11=$F$11,F19,IF($C$11=G$11,G19,IF($C$11=H$11,H19,IF($C$11=I$11,I19,IF($C$11=J$11,J19,IF($C$11=K$11,K19,IF($C$11=L$11,L19,IF($C$11=M$11,M19,N19)))))))) -> 757.35 | E19: Complemento Específico | F19: 806.35 | G19: 759.63 | H19: =+G19 -> 759.63 | I19: 757.35 | J19: =+I19 -> 757.35 | K19: =+J19 -> 757.35 | L19: =+K19 -> 757.35 | M19: 816.85 | N19: 1515.22
B20: Extra Complemento Específico Autonómico | C20: =IF($C$11=$F$11,F20,IF($C$11=G$11,G20,IF($C$11=H$11,H20,IF($C$11=I$11,I20,IF($C$11=J$11,J20,IF($C$11=K$11,K20,IF($C$11=L$11,L20,IF($C$11=M$11,M20,N20)))))))) -> 590.73 | E20: Extra Complemento Específico | F20: 628.95 | G20: 592.51 | H20: =+G20 -> 592.51 | I20: 590.73 | J20: =+I20 -> 590.73 | K20: =+J20 -> 590.73 | L20: =+K20 -> 590.73 | M20: 637.15 | N20: =+M20 -> 637.15
B21: Sin sexenio | C21: =IF($C$11=$F$11,F21,IF($C$11=G$11,G21,IF($C$11=H$11,H21,IF($C$11=I$11,I21,IF($C$11=J$11,J21,IF($C$11=K$11,K21,IF($C$11=L$11,L21,IF($C$11=M$11,M21,N21)))))))) -> 0 | E21: Sin sexenio | Z21: SEXENIOS EXTRA
B22: 1º Sexenio | C22: =IF($C$11=$F$11,F22,IF($C$11=G$11,G22,IF($C$11=H$11,H22,IF($C$11=I$11,I22,IF($C$11=J$11,J22,IF($C$11=K$11,K22,IF($C$11=L$11,L22,IF($C$11=M$11,M22,N22)))))))) -> 55 | E22: 1º Sexenio | F22: 55 | G22: =+F22 -> 55 | H22: =+G22 -> 55 | I22: =+H22 -> 55 | J22: =+I22 -> 55 | K22: =+J22 -> 55 | L22: =+K22 -> 55 | M22: =+L22 -> 55 | N22: =+M22 -> 55 | Z22: 42.9 | AA22: =+Z22 -> 42.9 | AB22: =+AA22 -> 42.9 | AC22: =+AB22 -> 42.9 | AD22: =+AC22 -> 42.9 | AE22: =+AD22 -> 42.9 | AF22: =+AE22 -> 42.9 | AG22: =+AF22 -> 42.9 | AH22: =+AG22 -> 42.9
B23: 2º Sexenio | C23: =IF($C$11=$F$11,F23,IF($C$11=G$11,G23,IF($C$11=H$11,H23,IF($C$11=I$11,I23,IF($C$11=J$11,J23,IF($C$11=K$11,K23,IF($C$11=L$11,L23,IF($C$11=M$11,M23,N23)))))))) -> 64 | E23: 2º Sexenio | F23: 64 | G23: =+F23 -> 64 | H23: =+G23 -> 64 | I23: =+H23 -> 64 | J23: =+I23 -> 64 | K23: =+J23 -> 64 | L23: =+K23 -> 64 | M23: =+L23 -> 64 | N23: =+M23 -> 64 | Z23: 49.92 | AA23: =+Z23 -> 49.92 | AB23: =+AA23 -> 49.92 | AC23: =+AB23 -> 49.92 | AD23: =+AC23 -> 49.92 | AE23: =+AD23 -> 49.92 | AF23: =+AE23 -> 49.92 | AG23: =+AF23 -> 49.92 | AH23: =+AG23 -> 49.92
B24: 3º Sexenio | C24: =IF($C$11=$F$11,F24,IF($C$11=G$11,G24,IF($C$11=H$11,H24,IF($C$11=I$11,I24,IF($C$11=J$11,J24,IF($C$11=K$11,K24,IF($C$11=L$11,L24,IF($C$11=M$11,M24,N24)))))))) -> 120 | E24: 3º Sexenio | F24: 120 | G24: =+F24 -> 120 | H24: =+G24 -> 120 | I24: =+H24 -> 120 | J24: =+I24 -> 120 | K24: =+J24 -> 120 | L24: =+K24 -> 120 | M24: =+L24 -> 120 | N24: =+M24 -> 120 | Z24: 93.6 | AA24: =+Z24 -> 93.6 | AB24: =+AA24 -> 93.6 | AC24: =+AB24 -> 93.6 | AD24: =+AC24 -> 93.6 | AE24: =+AD24 -> 93.6 | AF24: =+AE24 -> 93.6 | AG24: =+AF24 -> 93.6 | AH24: =+AG24 -> 93.6
B25: 4º Sexenio | C25: =IF($C$11=$F$11,F25,IF($C$11=G$11,G25,IF($C$11=H$11,H25,IF($C$11=I$11,I25,IF($C$11=J$11,J25,IF($C$11=K$11,K25,IF($C$11=L$11,L25,IF($C$11=M$11,M25,N25)))))))) -> 180 | E25: 4º Sexenio | F25: 180 | G25: =+F25 -> 180 | H25: =+G25 -> 180 | I25: =+H25 -> 180 | J25: =+I25 -> 180 | K25: =+J25 -> 180 | L25: =+K25 -> 180 | M25: =+L25 -> 180 | N25: =+M25 -> 180 | Z25: 140.4 | AA25: =+Z25 -> 140.4 | AB25: =+AA25 -> 140.4 | AC25: =+AB25 -> 140.4 | AD25: =+AC25 -> 140.4 | AE25: =+AD25 -> 140.4 | AF25: =+AE25 -> 140.4 | AG25: =+AF25 -> 140.4 | AH25: =+AG25 -> 140.4
B26: 5º Sexenio | C26: =IF($C$11=$F$11,F26,IF($C$11=G$11,G26,IF($C$11=H$11,H26,IF($C$11=I$11,I26,IF($C$11=J$11,J26,IF($C$11=K$11,K26,IF($C$11=L$11,L26,IF($C$11=M$11,M26,N26)))))))) -> 70 | E26: 5º Sexenio | F26: 70 | G26: =+F26 -> 70 | H26: =+G26 -> 70 | I26: =+H26 -> 70 | J26: =+I26 -> 70 | K26: =+J26 -> 70 | L26: =+K26 -> 70 | M26: =+L26 -> 70 | N26: =+M26 -> 70 | Z26: 54.6 | AA26: =+Z26 -> 54.6 | AB26: =+AA26 -> 54.6 | AC26: =+AB26 -> 54.6 | AD26: =+AC26 -> 54.6 | AE26: =+AD26 -> 54.6 | AF26: =+AE26 -> 54.6 | AG26: =+AF26 -> 54.6 | AH26: =+AG26 -> 54.6
B27: Tutoría | C27: =IF($C$11=$F$11,F27,IF($C$11=G$11,G27,IF($C$11=H$11,H27,IF($C$11=I$11,I27,IF($C$11=J$11,J27,IF($C$11=K$11,K27,IF($C$11=L$11,L27,IF($C$11=M$11,M27,N27)))))))) -> 35 | E27: Tutoría | F27: 35 | G27: =+F27 -> 35 | H27: =+G27 -> 35 | I27: =+H27 -> 35 | J27: =+I27 -> 35 | K27: =+J27 -> 35 | L27: =+K27 -> 35 | M27: =+L27 -> 35
B28: Cargo directivo | C28: =IF($C$11=$F$11,F28,IF($C$11=G$11,G28,IF($C$11=H$11,H28,IF($C$11=I$11,I28,IF($C$11=J$11,J28,IF($C$11=K$11,K28,IF($C$11=L$11,L28,IF($C$11=M$11,M28,N28)))))))) -> 253.88 | E28: Cargo directivo | F28: =IF($C$1=F11,'Nómina mensual'!$G$29,0) -> 0 | G28: =IF($C$1=G11,'Nómina mensual'!$G$29,0) -> 0 | H28: =IF($C$1=H11,'Nómina mensual'!$G$29,0) -> 0 | I28: =IF($C$1=I11,'Nómina mensual'!$G$29,0) -> 253.88 | J28: =IF($C$1=J11,'Nómina mensual'!$G$29,0) -> 0 | K28: =IF($C$1=K11,'Nómina mensual'!$G$29,0) -> 0 | L28: =IF($C$1=L11,'Nómina mensual'!$G$29,0) -> 0 | M28: =IF($C$1=M11,'Nómina mensual'!$G$29,0) -> 0
B29: Residencia Isla Capitalina | C29: =IF($C$11=$F$11,F29,IF($C$11=G$11,G29,IF($C$11=H$11,H29,IF($C$11=I$11,I29,IF($C$11=J$11,J29,IF($C$11=K$11,K29,IF($C$11=L$11,L29,IF($C$11=M$11,M29,N29)))))))) -> 160.59 | E29: Residencia Isla Capitalina | F29: 144.55 | G29: =+F29 -> 144.55 | H29: =+G29 -> 144.55 | I29: 160.59 | J29: =+I29 -> 160.59 | K29: =+J29 -> 160.59 | L29: =+K29 -> 160.59 | M29: 180.67 | N29: 178.29
B30: Residencia Isla No Capitalina | C30: =IF($C$11=$F$11,F30,IF($C$11=G$11,G30,IF($C$11=H$11,H30,IF($C$11=I$11,I30,IF($C$11=J$11,J30,IF($C$11=K$11,K30,IF($C$11=L$11,L30,IF($C$11=M$11,M30,N30)))))))) -> 534.9 | E30: Residencia Isla No Capitalina | F30: 481.43 | G30: =+F30 -> 481.43 | H30: =+G30 -> 481.43 | I30: 534.9 | J30: =+I30 -> 534.9 | K30: =+J30 -> 534.9 | L30: =+K30 -> 534.9 | M30: 601.77 | N30: 594.06
B31: Trienios Residencia Isla No Capitalina | C31: =IF($C$11=$F$11,F31,IF($C$11=G$11,G31,IF($C$11=H$11,H31,IF($C$11=I$11,I31,IF($C$11=J$11,J31,IF($C$11=K$11,K31,IF($C$11=L$11,L31,IF($C$11=M$11,M31,N31)))))))) -> 37.63 | E31: Trienios Residencia Isla No Capitalina | F31: 33.84 | G31: =+F31 -> 33.84 | H31: =+G31 -> 33.84 | I31: 37.63 | J31: =+I31 -> 37.63 | K31: =+J31 -> 37.63 | L31: =+K31 -> 37.63 | M31: 42.25 | N31: 90.28
B32: Adicional maestros 1º y 2º ESO | C32: =IF($C$11=$F$11,F32,IF($C$11=G$11,G32,IF($C$11=H$11,H32,IF($C$11=I$11,I32,IF($C$11=J$11,J32,IF($C$11=K$11,K32,IF($C$11=L$11,L32,IF($C$11=M$11,M32,N32)))))))) -> 0 | E32: Adicional maestros 1º y 2º ESO | F32: 70.34
B33: Complemento mejora/especial dedicación | C33: =IF($C$11=$F$11,F33,IF($C$11=G$11,G33,IF($C$11=H$11,H33,IF($C$11=I$11,I33,IF($C$11=J$11,J33,IF($C$11=K$11,K33,IF($C$11=L$11,L33,IF($C$11=M$11,M33,N33)))))))) -> 0 | E33: Extra Adicional maestros 1º y 2º ESO | F33: 68.31
B34: Productividad semestral (Murcia) | C34: =IF($C$11=$F$11,F34,IF($C$11=G$11,G34,IF($C$11=H$11,H34,IF($C$11=I$11,I34,IF($C$11=J$11,J34,IF($C$11=K$11,K34,IF($C$11=L$11,L34,IF($C$11=M$11,M34,N34)))))))) -> 0 | E34: Productividad semestral (Murcia)
B35: Reducción 3% (Castilla la Mancha) | C35: =IF($C$11=$F$11,F35,IF($C$11=G$11,G35,IF($C$11=H$11,H35,IF($C$11=I$11,I35,IF($C$11=J$11,J35,IF($C$11=K$11,K35,IF($C$11=L$11,L35,IF($C$11=M$11,M35,N35)))))))) -> 0 | E35: Reducción 3% (Castilla la Mancha)
B36: Otros | C36: =IF($C$11=$F$11,F36,IF($C$11=G$11,G36,IF($C$11=H$11,H36,IF($C$11=I$11,I36,IF($C$11=J$11,J36,IF($C$11=K$11,K36,IF($C$11=L$11,L36,IF($C$11=M$11,M36,N36)))))))) -> 0 | E36: Otros
E37: Dirección
E38: Vicedirección
E39: Jefatura de Estudios
E40: Secretaría
B41: MUFACE | C41: =IF($C$11=$F$11,F41,IF($C$11=G$11,G41,IF($C$11=H$11,H41,IF($C$11=I$11,I41,IF($C$11=J$11,J41,IF($C$11=K$11,K41,IF($C$11=L$11,L41,IF($C$11=M$11,M41,N41)))))))) -> -51.68 | E41: MUFACE | F41: =+F77 -> -40.68 | G41: =+G77 -> -40.68 | H41: =+H77 -> -40.68 | I41: =+I77 -> -51.68 | J41: =+J77 -> -51.68 | K41: =+K77 -> -51.68 | L41: =+L77 -> -51.68 | M41: =+M77 -> -51.68 | N41: =+N77 -> -51.68
...

Sheet DATOS
A1: ARAGÓN: | B1: Tiene importes diferentes en lo ssexenios mensuales, que en los sexenios de las pagas extras
A2: CANARIAS:
A3: BALEARES: | B3: Tienen complemento autonómico para funcionarios en prácticas e interinos, y otro para funcionarios de carrera escalable por antigüedad (como sexenios). También acuerdo de difícil cobertura difrente por islas, y una indemnización por residencia que también cambia en función del grupo profesional (A1, A2)
A4: CANARIAS: | B4: Las extras tienen los sexenios reducidos. El complemento específico en la extra es menor que en las pagas ordinarias. Los trienios en isla no capitalina son menores
A5: CANTABRIA
A6: CASTILLA LA MANCHA:
A7: MADRID: | B7: Los cargos directivos tienen un componente fijo y otro variable en función del número de alumnos matriculados
A8: MURCIA:
A9: NAVARRA: | B9: Antigüedad mediante escala de grados y quinquenios. No tienen complemento de destino. El sueldo base es más alto
